sample/market_data_spot_BTCUSDT_sample.csv
recv_tsec,recv_tnsec,venue,stream_kind,shard_id,conn_epoch,conn_seq,symbol,payload_json
1780861676,491371547,spot,depth5,0,0,1,BTCUSDT,"{""lastUpdateId"":95286421357,""bids"":[[""61222.00000000"",""0.88634000""],[""61221.99000000"",""0.00107000""],[""61221.98000000"",""0.00017000""],[""61221.50000000"",""0.00018000""],[""61221.49000000"",""0.04123000""]],""asks"":[[""61222.01000000"",""1.83509000""],[""61222.02000000"",""0.00080000""],[""61222.03000000"",""0.00017000""],[""61222.54000000"",""0.00027000""],[""61223.10000000"",""0.00018000""]]}"
1780861676,491439919,spot,depth_diff,0,0,2,BTCUSDT,"{""e"":""depthUpdate"",""E"":1780861677414,""s"":""BTCUSDT"",""U"":95286421334,""u"":95286421357,""b"":[[""61222.00000000"",""0.88634000""],[""61221.02000000"",""0.18253000""],[""61218.26000000"",""0.00000000""],[""61218.25000000"",""0.00018000""],[""61218.24000000"",""0.04698000""],[""61218.01000000"",""0.00018000""],[""61204.48000000"",""0.00000000""],[""61203.83000000"",""0.00200000""],[""59997.56000000"",""0.00415000""],[""55099.80000000"",""0.00510000""]],""a"":[[""61224.53000000"",""0.05119000""],[""61225.70000000"",""0.00000000""],[""61225.71000000"",""0.00018000""],[""61240.57000000"",""0.00200000""],[""61241.22000000"",""0.00000000""],[""61246.50000000"",""0.00306000""]]}"
1780861677,775736272,spot,depth5,0,0,3,BTCUSDT,"{""lastUpdateId"":95286421399,""bids"":[[""61222.00000000"",""0.88625000""],[""61221.99000000"",""0.00116000""],[""61221.98000000"",""0.00017000""],[""61221.50000000"",""0.00018000""],[""61221.49000000"",""0.04123000""]],""asks"":[[""61222.01000000"",""1.83509000""],[""61222.02000000"",""0.00080000""],[""61222.03000000"",""0.00017000""],[""61222.54000000"",""0.00027000""],[""61223.10000000"",""0.00018000""]]}"
1780861677,775753495,spot,depth_diff,0,0,4,BTCUSDT,"{""e"":""depthUpdate"",""E"":1780861677514,""s"":""BTCUSDT"",""U"":95286421358,""u"":95286421399,""b"":[[""61222.00000000"",""0.88625000""],[""61221.99000000"",""0.00116000""],[""61218.70000000"",""0.06914000""],[""61218.25000000"",""0.00009000""],[""61218.24000000"",""0.04716000""],[""55099.80000000"",""0.00510000""],[""48977.60000000"",""0.00040000""]],""a"":[[""61222.01000000"",""1.83509000""],[""61222.02000000"",""0.00080000""],[""61224.21000000"",""0.07613000""],[""61224.52000000"",""0.00018000""],[""61224.53000000"",""0.05137000""],[""61225.31000000"",""0.07488000""],[""61225.71000000"",""0.00000000""]]}"
1780861677,775761516,spot,depth5,0,0,5,BTCUSDT,"{""lastUpdateId"":95286421426,""bids"":[[""61222.00000000"",""0.88616000""],[""61221.99000000"",""0.00107000""],[""61221.98000000"",""0.00017000""],[""61221.50000000"",""0.00018000""],[""61221.49000000"",""0.04123000""]],""asks"":[[""61222.01000000"",""1.83509000""],[""61222.02000000"",""0.00080000""],[""61222.03000000"",""0.00017000""],[""61222.54000000"",""0.00027000""],[""61223.10000000"",""0.00018000""]]}"
1780861677,775768635,spot,depth_diff,0,0,6,BTCUSDT,"{""e"":""depthUpdate"",""E"":1780861677614,""s"":""BTCUSDT"",""U"":95286421400,""u"":95286421426,""b"":[[""61222.00000000"",""0.88616000""],[""61221.99000000"",""0.00107000""],[""61218.71000000"",""0.00000000""],[""61218.70000000"",""0.00018000""],[""61218.25000000"",""0.00018000""],[""61218.01000000"",""0.00009000""],[""61218.00000000"",""0.00027000""],[""61209.37000000"",""0.00000000""],[""61208.08000000"",""0.00000000""],[""61197.51000000"",""0.00000000""],[""61185.26000000"",""0.00306000""],[""55099.80000000"",""0.00510000""],[""48977.60000000"",""0.00000000""],[""35888.88000000"",""0.14648000""]],""a"":[[""61222.01000000"",""1.83509000""],[""61222.02000000"",""0.00080000""],[""61225.30000000"",""0.00000000""],[""61246.50000000"",""0.00612000""],[""61258.75000000"",""0.00000000""]]}"
1780861677,775780787,spot,depth5,0,0,7,BTCUSDT,"{""lastUpdateId"":95286421482,""bids"":[[""61222.00000000"",""0.87160000""],[""61221.99000000"",""0.00107000""],[""61221.98000000"",""0.00017000""],[""61221.50000000"",""0.00018000""],[""61221.49000000"",""0.04123000""]],""asks"":[[""61222.01000000"",""1.83491000""],[""61222.02000000"",""0.00062000""],[""61222.03000000"",""0.00017000""],[""61222.54000000"",""0.00027000""],[""61223.10000000"",""0.00018000""]]}"
1780861677,775786116,spot,depth_diff,0,0,8,BTCUSDT,"{""e"":""depthUpdate"",""E"":1780861677714,""s"":""BTCUSDT"",""U"":95286421427,""u"":95286421482,""b"":[[""61222.00000000"",""0.87160000""],[""61221.99000000"",""0.00107000""],[""61220.68000000"",""0.67626000""],[""61218.70000000"",""0.00000000""],[""61218.26000000"",""0.00018000""],[""61218.25000000"",""0.04669000""],[""61218.24000000"",""0.00018000""],[""61218.00000000"",""0.00009000""],[""61216.92000000"",""0.00800000""],[""61216.01000000"",""0.07605000""],[""61216.00000000"",""0.31724000""],[""61203.83000000"",""0.00000000""],[""61203.77000000"",""0.00200000""],[""55099.80000000"",""0.00510000""]],""a"":[[""61222.01000000"",""1.83491000""],[""61222.02000000"",""0.00062000""],[""61224.52000000"",""0.00000000""],[""61224.53000000"",""0.00018000""],[""61225.31000000"",""0.07497000""],[""61225.71000000"",""0.07818000""],[""61226.34000000"",""0.18197000""],[""61229.44000000"",""0.00000000""],[""61240.51000000"",""0.00200000""],[""61240.57000000"",""0.00000000""],[""86422.88000000"",""0.01891000""]]}"
1780861677,775796396,spot,trade,0,0,9,BTCUSDT,"{""e"":""trade"",""E"":1780861677732,""s"":""BTCUSDT"",""t"":6383873125,""p"":""61222.00000000"",""q"":""0.03007000"",""T"":1780861677732,""m"":true,""M"":true}"
1780861677,775799320,spot,depth5,0,0,10,BTCUSDT,"{""lastUpdateId"":95286421553,""bids"":[[""61222.00000000"",""0.58226000""],[""61221.99000000"",""0.00107000""],[""61221.98000000"",""0.00017000""],[""61221.50000000"",""0.00018000""],[""61221.49000000"",""0.00018000""]],""asks"":[[""61222.01000000"",""1.83473000""],[""61222.02000000"",""0.00044000""],[""61222.03000000"",""0.00017000""],[""61222.54000000"",""0.00027000""],[""61223.11000000"",""0.07604000""]]}"
1780861677,775804408,spot,depth_diff,0,0,11,BTCUSDT,"{""e"":""depthUpdate"",""E"":1780861677814,""s"":""BTCUSDT"",""U"":95286421483,""u"":95286421553,""b"":[[""61222.00000000"",""0.58226000""],[""61221.49000000"",""0.00018000""],[""61220.68000000"",""0.67626000""],[""61218.25000000"",""0.04687000""],[""61218.24000000"",""0.00000000""],[""61217.99000000"",""0.34442000""],[""61216.92000000"",""0.00818000""],[""61216.55000000"",""0.00000000""],[""61216.50000000"",""0.00018000""],[""61216.01000000"",""0.04123000""],[""61216.00000000"",""0.31706000""],[""61215.52000000"",""0.00000000""],[""61215.03000000"",""0.00000000""],[""61214.92000000"",""0.00000000""],[""61214.31000000"",""0.00326000""],[""61214.30000000"",""0.00009000""],[""61213.71000000"",""0.00201000""],[""61212.59000000"",""0.07054000""],[""61207.98000000"",""0.00000000""],[""61203.23000000"",""0.00400000""],[""56324.24000000"",""0.00000000""],[""55099.80000000"",""0.00510000""]],""a"":[[""61222.01000000"",""1.83473000""],[""61222.02000000"",""0.00044000""],[""61223.10000000"",""0.00000000""],[""61224.20000000"",""0.00000000""],[""61224.21000000"",""0.07604000""],[""61224.53000000"",""0.00000000""],[""61225.31000000"",""0.07497000""],[""61225.71000000"",""0.07836000""],[""61226.34000000"",""0.18215000""],[""61228.28000000"",""1.86042000""],[""61234.85000000"",""0.07578000""],[""86422.88000000"",""0.03782000""]]}"
1780861677,775814328,spot,trade,0,0,12,BTCUSDT,"{""e"":""trade"",""E"":1780861677891,""s"":""BTCUSDT"",""t"":6383873126,""p"":""61222.00000000"",""q"":""0.00440000"",""T"":1780861677890,""m"":true,""M"":true}"
1780861677,775817838,spot,depth5,0,0,13,BTCUSDT,"{""lastUpdateId"":95286421601,""bids"":[[""61222.00000000"",""0.76028000""],[""61221.99000000"",""0.00107000""],[""61221.98000000"",""0.00017000""],[""61221.31000000"",""0.00009000""],[""61221.16000000"",""0.00009000""]],""asks"":[[""61222.01000000"",""1.83491000""],[""61222.02000000"",""0.00062000""],[""61222.03000000"",""0.00017000""],[""61222.54000000"",""0.00027000""],[""61223.10000000"",""0.00018000""]]}"
